06-22 20:47:25 [ERROR] uvicorn | Traceback (most recent call last):
  File "C:\Users\15185\.virtualenvs\zhenxun\lib\site-packages\starlette\routing.py", line 635, in lifespan
    async with self.lifespan_context(app):
  File "C:\Users\15185\.virtualenvs\zhenxun\lib\site-packages\starlette\routing.py", line 530, in __aenter__
    await self._router.startup()
  File "C:\Users\15185\.virtualenvs\zhenxun\lib\site-packages\starlette\routing.py", line 612, in startup
    await handler()
  File "D:\workspace\robot\zhenxun\zhenxun\services\db_context.py", line 14, in init
    raise ValueError("\n" + prompt2cn("数据库配置未填写", 28))
ValueError: 
############################
###### 数据库配置未填写 ######
############################

06-22 20:47:25 [ERROR] uvicorn | Application startup failed. Exiting.
06-22 20:49:31 [ERROR] uvicorn | Traceback (most recent call last):
  File "C:\Users\15185\.virtualenvs\zhenxun\lib\site-packages\starlette\routing.py", line 635, in lifespan
    async with self.lifespan_context(app):
  File "C:\Users\15185\.virtualenvs\zhenxun\lib\site-packages\starlette\routing.py", line 530, in __aenter__
    await self._router.startup()
  File "C:\Users\15185\.virtualenvs\zhenxun\lib\site-packages\starlette\routing.py", line 612, in startup
    await handler()
  File "D:\workspace\robot\zhenxun\zhenxun\basic_plugins\scripts.py", line 121, in _
    await db.first(query)
  File "C:\Users\15185\.virtualenvs\zhenxun\lib\site-packages\gino\api.py", line 479, in first
    return await self.bind.first(clause, *multiparams, **params)
  File "C:\Users\15185\.virtualenvs\zhenxun\lib\site-packages\gino\engine.py", line 748, in first
    return await conn.first(clause, *multiparams, **params)
  File "C:\Users\15185\.virtualenvs\zhenxun\lib\site-packages\gino\engine.py", line 328, in first
    return await result.execute(one=True)
  File "C:\Users\15185\.virtualenvs\zhenxun\lib\site-packages\gino\dialects\base.py", line 214, in execute
    rows = await cursor.async_execute(
  File "C:\Users\15185\.virtualenvs\zhenxun\lib\site-packages\gino\dialects\asyncpg.py", line 184, in async_execute
    result, stmt = await getattr(conn, "_do_execute")(query, executor, timeout)
  File "C:\Users\15185\.virtualenvs\zhenxun\lib\site-packages\asyncpg\connection.py", line 1731, in _do_execute
    result = await executor(stmt, None)
  File "asyncpg\protocol\protocol.pyx", line 201, in bind_execute
asyncpg.exceptions.UndefinedTableError: relation "open_cases_users" does not exist

06-22 20:49:31 [ERROR] uvicorn | Application startup failed. Exiting.
06-22 20:51:16 [ERROR] uvicorn | Traceback (most recent call last):
  File "C:\Users\15185\.virtualenvs\zhenxun\lib\site-packages\starlette\routing.py", line 635, in lifespan
    async with self.lifespan_context(app):
  File "C:\Users\15185\.virtualenvs\zhenxun\lib\site-packages\starlette\routing.py", line 530, in __aenter__
    await self._router.startup()
  File "C:\Users\15185\.virtualenvs\zhenxun\lib\site-packages\starlette\routing.py", line 614, in startup
    handler()
  File "D:\workspace\robot\zhenxun\zhenxun\basic_plugins\init_plugin_config\__init__.py", line 53, in _
    raise Exception("首次运行，已在configs目录下生成配置文件config.yaml，修改后重启即可...")
Exception: 首次运行，已在configs目录下生成配置文件config.yaml，修改后重启即可...

06-22 20:51:16 [ERROR] uvicorn | Application startup failed. Exiting.
06-22 20:52:12 [ERROR] uvicorn | Traceback (most recent call last):
  File "C:\Users\15185\.virtualenvs\zhenxun\lib\site-packages\starlette\routing.py", line 635, in lifespan
    async with self.lifespan_context(app):
  File "C:\Users\15185\.virtualenvs\zhenxun\lib\site-packages\starlette\routing.py", line 530, in __aenter__
    await self._router.startup()
  File "C:\Users\15185\.virtualenvs\zhenxun\lib\site-packages\starlette\routing.py", line 612, in startup
    await handler()
  File "D:\workspace\robot\zhenxun\zhenxun\basic_plugins\scripts.py", line 121, in _
    await db.first(query)
  File "C:\Users\15185\.virtualenvs\zhenxun\lib\site-packages\gino\api.py", line 479, in first
    return await self.bind.first(clause, *multiparams, **params)
  File "C:\Users\15185\.virtualenvs\zhenxun\lib\site-packages\gino\engine.py", line 748, in first
    return await conn.first(clause, *multiparams, **params)
  File "C:\Users\15185\.virtualenvs\zhenxun\lib\site-packages\gino\engine.py", line 328, in first
    return await result.execute(one=True)
  File "C:\Users\15185\.virtualenvs\zhenxun\lib\site-packages\gino\dialects\base.py", line 214, in execute
    rows = await cursor.async_execute(
  File "C:\Users\15185\.virtualenvs\zhenxun\lib\site-packages\gino\dialects\asyncpg.py", line 184, in async_execute
    result, stmt = await getattr(conn, "_do_execute")(query, executor, timeout)
  File "C:\Users\15185\.virtualenvs\zhenxun\lib\site-packages\asyncpg\connection.py", line 1731, in _do_execute
    result = await executor(stmt, None)
  File "asyncpg\protocol\protocol.pyx", line 201, in bind_execute
asyncpg.exceptions.UndefinedTableError: relation "open_cases_users" does not exist

06-22 20:52:12 [ERROR] uvicorn | Application startup failed. Exiting.
06-22 20:52:47 [ERROR] uvicorn | Traceback (most recent call last):
  File "C:\Users\15185\.virtualenvs\zhenxun\lib\site-packages\starlette\routing.py", line 635, in lifespan
    async with self.lifespan_context(app):
  File "C:\Users\15185\.virtualenvs\zhenxun\lib\site-packages\starlette\routing.py", line 530, in __aenter__
    await self._router.startup()
  File "C:\Users\15185\.virtualenvs\zhenxun\lib\site-packages\starlette\routing.py", line 612, in startup
    await handler()
  File "D:\workspace\robot\zhenxun\zhenxun\basic_plugins\scripts.py", line 121, in _
    await db.first(query)
  File "C:\Users\15185\.virtualenvs\zhenxun\lib\site-packages\gino\api.py", line 479, in first
    return await self.bind.first(clause, *multiparams, **params)
  File "C:\Users\15185\.virtualenvs\zhenxun\lib\site-packages\gino\engine.py", line 748, in first
    return await conn.first(clause, *multiparams, **params)
  File "C:\Users\15185\.virtualenvs\zhenxun\lib\site-packages\gino\engine.py", line 328, in first
    return await result.execute(one=True)
  File "C:\Users\15185\.virtualenvs\zhenxun\lib\site-packages\gino\dialects\base.py", line 214, in execute
    rows = await cursor.async_execute(
  File "C:\Users\15185\.virtualenvs\zhenxun\lib\site-packages\gino\dialects\asyncpg.py", line 184, in async_execute
    result, stmt = await getattr(conn, "_do_execute")(query, executor, timeout)
  File "C:\Users\15185\.virtualenvs\zhenxun\lib\site-packages\asyncpg\connection.py", line 1731, in _do_execute
    result = await executor(stmt, None)
  File "asyncpg\protocol\protocol.pyx", line 201, in bind_execute
asyncpg.exceptions.UndefinedTableError: relation "genshin" does not exist

06-22 20:52:47 [ERROR] uvicorn | Application startup failed. Exiting.
06-22 20:54:00 [ERROR] plugins | Traceback (most recent call last):
  File "C:\Users\15185\.virtualenvs\zhenxun\lib\site-packages\anyio\streams\tls.py", line 130, in _call_sslobject_method
    result = func(*args)
  File "C:\Program Files\Python\Python39\lib\ssl.py", line 944, in do_handshake
    self._sslobj.do_handshake()
ssl.SSLSyscallError: Some I/O error occurred (_ssl.c:1129)

The above exception was the direct cause of the following exception:

Traceback (most recent call last):
  File "C:\Users\15185\.virtualenvs\zhenxun\lib\site-packages\httpcore\_exceptions.py", line 8, in map_exceptions
    yield
  File "C:\Users\15185\.virtualenvs\zhenxun\lib\site-packages\httpcore\backends\asyncio.py", line 76, in start_tls
    raise exc
  File "C:\Users\15185\.virtualenvs\zhenxun\lib\site-packages\httpcore\backends\asyncio.py", line 67, in start_tls
    ssl_stream = await anyio.streams.tls.TLSStream.wrap(
  File "C:\Users\15185\.virtualenvs\zhenxun\lib\site-packages\anyio\streams\tls.py", line 122, in wrap
    await wrapper._call_sslobject_method(ssl_object.do_handshake)
  File "C:\Users\15185\.virtualenvs\zhenxun\lib\site-packages\anyio\streams\tls.py", line 151, in _call_sslobject_method
    raise BrokenResourceError from exc
anyio.BrokenResourceError

During handling of the above exception, another exception occurred:

Traceback (most recent call last):
  File "C:\Users\15185\.virtualenvs\zhenxun\lib\site-packages\httpx\_transports\default.py", line 60, in map_httpcore_exceptions
    yield
  File "C:\Users\15185\.virtualenvs\zhenxun\lib\site-packages\httpx\_transports\default.py", line 353, in handle_async_request
    resp = await self._pool.handle_async_request(req)
  File "C:\Users\15185\.virtualenvs\zhenxun\lib\site-packages\httpcore\_async\connection_pool.py", line 253, in handle_async_request
    raise exc
  File "C:\Users\15185\.virtualenvs\zhenxun\lib\site-packages\httpcore\_async\connection_pool.py", line 237, in handle_async_request
    response = await connection.handle_async_request(request)
  File "C:\Users\15185\.virtualenvs\zhenxun\lib\site-packages\httpcore\_async\http_proxy.py", line 258, in handle_async_request
    connect_response = await self._connection.handle_async_request(
  File "C:\Users\15185\.virtualenvs\zhenxun\lib\site-packages\httpcore\_async\connection.py", line 86, in handle_async_request
    raise exc
  File "C:\Users\15185\.virtualenvs\zhenxun\lib\site-packages\httpcore\_async\connection.py", line 63, in handle_async_request
    stream = await self._connect(request)
  File "C:\Users\15185\.virtualenvs\zhenxun\lib\site-packages\httpcore\_async\connection.py", line 150, in _connect
    stream = await stream.start_tls(**kwargs)
  File "C:\Users\15185\.virtualenvs\zhenxun\lib\site-packages\httpcore\backends\asyncio.py", line 76, in start_tls
    raise exc
  File "C:\Program Files\Python\Python39\lib\contextlib.py", line 137, in __exit__
    self.gen.throw(typ, value, traceback)
  File "C:\Users\15185\.virtualenvs\zhenxun\lib\site-packages\httpcore\_exceptions.py", line 12, in map_exceptions
    raise to_exc(exc)
httpcore.ConnectError

The above exception was the direct cause of the following exception:

Traceback (most recent call last):
  File "D:\workspace\robot\zhenxun\zhenxun\plugins\hikari_bot\__init__.py", line 216, in startup
    resp = await client.get(url, timeout=20)
  File "C:\Users\15185\.virtualenvs\zhenxun\lib\site-packages\httpx\_client.py", line 1751, in get
    return await self.request(
  File "C:\Users\15185\.virtualenvs\zhenxun\lib\site-packages\httpx\_client.py", line 1527, in request
    return await self.send(request, auth=auth, follow_redirects=follow_redirects)
  File "C:\Users\15185\.virtualenvs\zhenxun\lib\site-packages\httpx\_client.py", line 1614, in send
    response = await self._send_handling_auth(
  File "C:\Users\15185\.virtualenvs\zhenxun\lib\site-packages\httpx\_client.py", line 1642, in _send_handling_auth
    response = await self._send_handling_redirects(
  File "C:\Users\15185\.virtualenvs\zhenxun\lib\site-packages\httpx\_client.py", line 1679, in _send_handling_redirects
    response = await self._send_single_request(request)
  File "C:\Users\15185\.virtualenvs\zhenxun\lib\site-packages\httpx\_client.py", line 1716, in _send_single_request
    response = await transport.handle_async_request(request)
  File "C:\Users\15185\.virtualenvs\zhenxun\lib\site-packages\httpx\_transports\default.py", line 353, in handle_async_request
    resp = await self._pool.handle_async_request(req)
  File "C:\Program Files\Python\Python39\lib\contextlib.py", line 137, in __exit__
    self.gen.throw(typ, value, traceback)
  File "C:\Users\15185\.virtualenvs\zhenxun\lib\site-packages\httpx\_transports\default.py", line 77, in map_httpcore_exceptions
    raise mapped_exc(message) from exc
httpx.ConnectError

